<?xml version="1.0" encoding="UTF-8"?>
<testng-results skipped="0" failed="2" ignored="0" total="3" passed="1">
  <reporter-output>
  </reporter-output>
  <suite name="Default suite" duration-ms="29283" started-at="2018-06-08T13:02:29Z" finished-at="2018-06-08T13:02:59Z">
    <groups>
    </groups>
    <test name="Default test" duration-ms="29283" started-at="2018-06-08T13:02:29Z" finished-at="2018-06-08T13:02:59Z">
      <class name="testSuites.LoginPage">
        <test-method status="FAIL" signature="LoginTest(java.lang.String, java.lang.String)[pri:0, instance:testSuites.LoginPage@8bd1b6a]" name="LoginTest" duration-ms="9347" started-at="2018-06-08T13:02:30Z" data-provider="ExcelData" finished-at="2018-06-08T13:02:39Z">
          <params>
            <param index="0">
              <value>
                <![CDATA[admin1]]>
              </value>
            </param>
            <param index="1">
              <value>
                <![CDATA[demo12]]>
              </value>
            </param>
          </params>
          <exception class="java.lang.AssertionError">
            <message>
              <![CDATA[expected [Dashboard ‹ Wordpress Demo Site at Demo.Center — WordPress] but found [Log In ‹ Wordpress Demo Site at Demo.Center — WordPress]]]>
            </message>
            <full-stacktrace>
              <![CDATA[java.lang.AssertionError: expected [Dashboard ‹ Wordpress Demo Site at Demo.Center — WordPress] but found [Log In ‹ Wordpress Demo Site at Demo.Center — WordPress]
at org.testng.Assert.fail(Assert.java:96)
at org.testng.Assert.failNotEquals(Assert.java:776)
at org.testng.Assert.assertEqualsImpl(Assert.java:137)
at org.testng.Assert.assertEquals(Assert.java:118)
at org.testng.Assert.assertEquals(Assert.java:453)
at org.testng.Assert.assertEquals(Assert.java:463)
at testSuites.LoginPage.LoginTest(LoginPage.java:33)
at sun.reflect.NativeMethodAccessorImpl.invoke0(Native Method)
at sun.reflect.NativeMethodAccessorImpl.invoke(Unknown Source)
at sun.reflect.DelegatingMethodAccessorImpl.invoke(Unknown Source)
at java.lang.reflect.Method.invoke(Unknown Source)
at org.testng.internal.MethodInvocationHelper.invokeMethod(MethodInvocationHelper.java:124)
at org.testng.internal.Invoker.invokeMethod(Invoker.java:580)
at org.testng.internal.Invoker.invokeTestMethod(Invoker.java:716)
at org.testng.internal.Invoker.invokeTestMethods(Invoker.java:988)
at org.testng.internal.TestMethodWorker.invokeTestMethods(TestMethodWorker.java:125)
at org.testng.internal.TestMethodWorker.run(TestMethodWorker.java:109)
at org.testng.TestRunner.privateRun(TestRunner.java:648)
at org.testng.TestRunner.run(TestRunner.java:505)
at org.testng.SuiteRunner.runTest(SuiteRunner.java:455)
at org.testng.SuiteRunner.runSequentially(SuiteRunner.java:450)
at org.testng.SuiteRunner.privateRun(SuiteRunner.java:415)
at org.testng.SuiteRunner.run(SuiteRunner.java:364)
at org.testng.SuiteRunnerWorker.runSuite(SuiteRunnerWorker.java:52)
at org.testng.SuiteRunnerWorker.run(SuiteRunnerWorker.java:84)
at org.testng.TestNG.runSuitesSequentially(TestNG.java:1208)
at org.testng.TestNG.runSuitesLocally(TestNG.java:1137)
at org.testng.TestNG.runSuites(TestNG.java:1049)
at org.testng.TestNG.run(TestNG.java:1017)
at org.testng.remote.AbstractRemoteTestNG.run(AbstractRemoteTestNG.java:114)
at org.testng.remote.RemoteTestNG.initAndRun(RemoteTestNG.java:251)
at org.testng.remote.RemoteTestNG.main(RemoteTestNG.java:77)
]]>
            </full-stacktrace>
          </exception> <!-- java.lang.AssertionError -->
          <reporter-output>
          </reporter-output>
        </test-method> <!-- LoginTest -->
        <test-method status="PASS" signature="LoginTest(java.lang.String, java.lang.String)[pri:0, instance:testSuites.LoginPage@8bd1b6a]" name="LoginTest" duration-ms="10632" started-at="2018-06-08T13:02:39Z" data-provider="ExcelData" finished-at="2018-06-08T13:02:50Z">
          <params>
            <param index="0">
              <value>
                <![CDATA[admin]]>
              </value>
            </param>
            <param index="1">
              <value>
                <![CDATA[demo123]]>
              </value>
            </param>
          </params>
          <reporter-output>
          </reporter-output>
        </test-method> <!-- LoginTest -->
        <test-method status="FAIL" signature="LoginTest(java.lang.String, java.lang.String)[pri:0, instance:testSuites.LoginPage@8bd1b6a]" name="LoginTest" duration-ms="8564" started-at="2018-06-08T13:02:50Z" data-provider="ExcelData" finished-at="2018-06-08T13:02:59Z">
          <params>
            <param index="0">
              <value>
                <![CDATA[admin2]]>
              </value>
            </param>
            <param index="1">
              <value>
                <![CDATA[demo1]]>
              </value>
            </param>
          </params>
          <exception class="java.lang.AssertionError">
            <message>
              <![CDATA[expected [Dashboard ‹ Wordpress Demo Site at Demo.Center — WordPress] but found [Log In ‹ Wordpress Demo Site at Demo.Center — WordPress]]]>
            </message>
            <full-stacktrace>
              <![CDATA[java.lang.AssertionError: expected [Dashboard ‹ Wordpress Demo Site at Demo.Center — WordPress] but found [Log In ‹ Wordpress Demo Site at Demo.Center — WordPress]
at org.testng.Assert.fail(Assert.java:96)
at org.testng.Assert.failNotEquals(Assert.java:776)
at org.testng.Assert.assertEqualsImpl(Assert.java:137)
at org.testng.Assert.assertEquals(Assert.java:118)
at org.testng.Assert.assertEquals(Assert.java:453)
at org.testng.Assert.assertEquals(Assert.java:463)
at testSuites.LoginPage.LoginTest(LoginPage.java:33)
at sun.reflect.NativeMethodAccessorImpl.invoke0(Native Method)
at sun.reflect.NativeMethodAccessorImpl.invoke(Unknown Source)
at sun.reflect.DelegatingMethodAccessorImpl.invoke(Unknown Source)
at java.lang.reflect.Method.invoke(Unknown Source)
at org.testng.internal.MethodInvocationHelper.invokeMethod(MethodInvocationHelper.java:124)
at org.testng.internal.Invoker.invokeMethod(Invoker.java:580)
at org.testng.internal.Invoker.invokeTestMethod(Invoker.java:716)
at org.testng.internal.Invoker.invokeTestMethods(Invoker.java:988)
at org.testng.internal.TestMethodWorker.invokeTestMethods(TestMethodWorker.java:125)
at org.testng.internal.TestMethodWorker.run(TestMethodWorker.java:109)
at org.testng.TestRunner.privateRun(TestRunner.java:648)
at org.testng.TestRunner.run(TestRunner.java:505)
at org.testng.SuiteRunner.runTest(SuiteRunner.java:455)
at org.testng.SuiteRunner.runSequentially(SuiteRunner.java:450)
at org.testng.SuiteRunner.privateRun(SuiteRunner.java:415)
at org.testng.SuiteRunner.run(SuiteRunner.java:364)
at org.testng.SuiteRunnerWorker.runSuite(SuiteRunnerWorker.java:52)
at org.testng.SuiteRunnerWorker.run(SuiteRunnerWorker.java:84)
at org.testng.TestNG.runSuitesSequentially(TestNG.java:1208)
at org.testng.TestNG.runSuitesLocally(TestNG.java:1137)
at org.testng.TestNG.runSuites(TestNG.java:1049)
at org.testng.TestNG.run(TestNG.java:1017)
at org.testng.remote.AbstractRemoteTestNG.run(AbstractRemoteTestNG.java:114)
at org.testng.remote.RemoteTestNG.initAndRun(RemoteTestNG.java:251)
at org.testng.remote.RemoteTestNG.main(RemoteTestNG.java:77)
]]>
            </full-stacktrace>
          </exception> <!-- java.lang.AssertionError -->
          <reporter-output>
          </reporter-output>
        </test-method> <!-- LoginTest -->
      </class> <!-- testSuites.LoginPage -->
    </test> <!-- Default test -->
  </suite> <!-- Default suite -->
</testng-results>
